Workbook

Sheet 課表
A1: 週 | B1: 日期 | C1: 星期 | D1: 階段 | E1: 類型 | F1: 計畫 km | G1: 配速 / 心拍 | H1: 內容 | I1: 備註（補給・肌力・提醒） | J1: 實際 km | K1: 完成 | L1: 心得 | M1: 時間 | N1: 平均配速 | O1: 平均心拍 | P1: 最大心拍 | Q1: 平均功率 W | R1: 卡路里 | S1: 天氣 / 氣溫 / 濕度 | T1: 鞋 | U1: 裝置
A2: 1 | B2: 46303 | C2: 四 | D2: 第一階段｜重建跑量 | E2: Easy | F2: 6 | G2: 7:15〜7:45 / 心拍 140〜150 | H2: 輕鬆跑 6 km | I2: 新鞋/舊鞋都行，先把習慣建起來 | J2: 7.27 | K2: ✅ | L2: 照課表跑，最後小走一段。Strava 判定 5K PB，心拍偏高（閾值區 79%） | M2: 45:29 | N2: 6:15 | O2: 169 | P2: 176 | Q2: 171 | R2: 498 | S2: 晴れ 19°C / 濕度 77% / 東南東風 5 km/h | T2: Adidas EVO SL | U2: Apple Watch Series 11
A3: 1 | B3: 46304 | C3: 五 | D3: 第一階段｜重建跑量 | E3: 休息 | F3: 0 | H3: 休息
A4: 1 | B4: 46305 | C4: 六 | D4: 第一階段｜重建跑量 | E4: Easy | F4: 5 | G4: 7:15〜7:45 / 心拍 140〜150 | H4: 輕鬆跑 5 km | J4: 5.22 | K4: ✅ | L4: 第一次成功壓住心拍的 Easy，GAP 7:03。第1km 6:23 偏快，後段心拍 141→156 微爬。路線爬升 91m 適合富士山 ／ 下午另做 Hyrox 58分（6站×2分），平均心拍152，難度9，隔天下半身痠痛 | M4: 38:40 | N4: 7:25 | O4: 150 | P4: 160 | R4: 355 | S4: 晴 19°C / 體感 21°C / 濕度 77% / 北風 7.2 km/h | T4: Adidas EVO SL | U4: Apple Watch Series 11
A5: 1 | B5: 46306 | C5: 日 | D5: 第一階段｜重建跑量 | E5: Long | F5: 12 | G5: 7:20〜7:50 | H5: 長跑 12 km，全程聊天配速 | I5: 跑完記錄心拍，當基準 | J5: 12.3 | K5: ✅ | L5: 第一次長跑。前半心拍146/後半152漂移+6，合格。前2km 7:19/7:13 偏快。4km處買水。前日Hyrox腿痠、27°C仍壓住心拍。基準線：27°C/HR149/7:40 | M5: 1:36:09 | N5: 7:47 | O5: 149 | P5: 162 | Q5: 138 | S5: 晴 27°C / 體感 28°C / 濕度 46% / 北東風 10.4 km/h | T5: Adidas EVO SL | U5: Apple Watch Series 11
A6: 2 | B6: 46307 | C6: 一 | D6: 第一階段｜重建跑量 | E6: 休息 | F6: 0 | H6: 休息 | I6: 完全休息。走路 20〜30 分 + 伸展滾筒（小腿／股四頭／臀）。腿痠散掉再跑
A7: 2 | B7: 46308 | C7: 二 | D7: 第一階段｜重建跑量 | E7: Easy | F7: 6 | G7: 7:15〜7:45 / 心拍 140〜150 | H7: 輕鬆跑 6 km
A8: 2 | B8: 46309 | C8: 三 | D8: 第一階段｜重建跑量 | E8: MP | F8: 7 | G8: MP 段 6:35〜6:50 | H8: 2 km Easy + 3 km @ MP + 2 km Easy | I8: MP 段心拍不要超過 165
A9: 2 | B9: 46310 | C9: 四 | D9: 第一階段｜重建跑量 | E9: 休息 | F9: 0 | H9: 休息 | I9: 休息。本週肌力由 10/17 Hyrox 取代，不做核心
A10: 2 | B10: 46311 | C10: 五 | D10: 第一階段｜重建跑量 | E10: Recovery | F10: 4 | G10: 心拍 ≤140 / 7:45+ | H10: 恢復跑 4 km | I10: 隔天 Hyrox，只活動腿，心拍超過 145 就走
A11: 2 | B11: 46312 | C11: 六 | D11: 第一階段｜重建跑量 | E11: 肌力 | F11: 0 | H11: Hyrox（已約） | I11: 難度 6〜7，站間休夠，心拍不衝 160+。這週肌力就是這場
A12: 2 | B12: 46313 | C12: 日 | D12: 第一階段｜重建跑量 | E12: Long | F12: 14 | G12: 7:15〜7:45 | H12: 長跑 14 km | I12: 前日 Hyrox。目標只有完成＋心拍 ≤150，配速掉到 8:00 也可。隔天腿痠 >1 天＝Hyrox 強度太高
A13: 3 | B13: 46314 | C13: 一 | D13: 第一階段｜重建跑量 | E13: 休息 | F13: 0 | H13: 休息
A14: 3 | B14: 46315 | C14: 二 | D14: 第一階段｜重建跑量 | E14: Easy | F14: 6 | G14: 7:15〜7:45 / 心拍 140〜150 | H14: 輕鬆跑 6 km
A15: 3 | B15: 46316 | C15: 三 | D15: 第一階段｜重建跑量 | E15: 坡跑 | F15: 8 | G15: 上坡 6:00 以內 / 下坡慢跑 | H15: 2 km Easy + 5×90 秒上坡（慢跑下坡回復）+ 2 km Easy | I15: 模擬富士山 20〜30 km 河口湖→西湖爬坡
A16: 3 | B16: 46317 | C16: 四 | D16: 第一階段｜重建跑量 | E16: 休息 | F16: 0 | H16: 休息 | I16: 肌力日：Hyrox 或 15 分鐘核心＋臀腿 擇一，難度 6〜7，不要跑到心拍 160+
A17: 3 | B17: 46318 | C17: 五 | D17: 第一階段｜重建跑量 | E17: Easy | F17: 6 | G17: 7:15〜7:45 / 心拍 140〜150 | H17: 輕鬆跑 6 km
A18: 3 | B18: 46319 | C18: 六 | D18: 第一階段｜重建跑量 | E18: 休息 | F18: 0 | H18: 休息
A19: 3 | B19: 46320 | C19: 日 | D19: 第一階段｜重建跑量 | E19: Long | F19: 16 | G19: 7:10〜7:40 | H19: 長跑 16 km | I19: 找有起伏的路線（駒沢、代代木）
A20: 4 | B20: 46321 | C20: 一 | D20: 第二階段｜馬拉松訓練 | E20: 休息 | F20: 0 | H20: 休息
A21: 4 | B21: 46322 | C21: 二 | D21: 第二階段｜馬拉松訓練 | E21: Easy | F21: 7 | G21: 7:15〜7:45 / 心拍 140〜150 | H21: 輕鬆跑 7 km
A22: 4 | B22: 46323 | C22: 三 | D22: 第二階段｜馬拉松訓練 | E22: MP | F22: 9 | G22: MP 段 6:40〜6:50 | H22: 3 km Easy + 5 km @ 6:40 + 1 km Easy
A23: 4 | B23: 46324 | C23: 四 | D23: 第二階段｜馬拉松訓練 | E23: 休息 | F23: 0 | H23: 休息 | I23: 肌力日：Hyrox 或 15 分鐘核心＋臀腿 擇一，難度 6〜7，不要跑到心拍 160+
A24: 4 | B24: 46325 | C24: 五 | D24: 第二階段｜馬拉松訓練 | E24: Easy | F24: 6 | G24: 7:15〜7:45 / 心拍 140〜150 | H24: 輕鬆跑 6 km
A25: 4 | B25: 46326 | C25: 六 | D25: 第二階段｜馬拉松訓練 | E25: 休息 | F25: 0 | H25: 休息
A26: 4 | B26: 46327 | C26: 日 | D26: 第二階段｜馬拉松訓練 | E26: Long | F26: 18 | G26: 7:10〜7:40 / 心拍 ≤155 | H26: 長跑 18 km，最後 4 km @ 6:45 | I26: 每 40 分 1 包能量膠＋水，測試腸胃；穿比賽衣褲
A27: 5 | B27: 46328 | C27: 一 | D27: 第二階段｜馬拉松訓練 | E27: 休息 | F27: 0 | H27: 休息
A28: 5 | B28: 46329 | C28: 二 | D28: 第二階段｜馬拉松訓練 | E28: Easy | F28: 7 | G28: 7:15〜7:45 / 心拍 140〜150 | H28: 輕鬆跑 7 km
A29: 5 | B29: 46330 | C29: 三 | D29: 第二階段｜馬拉松訓練 | E29: 坡跑 | F29: 8 | G29: 上坡 6:00 以內 | H29: 2 km Easy + 6×90 秒上坡 + 2 km Easy
A30: 5 | B30: 46331 | C30: 四 | D30: 第二階段｜馬拉松訓練 | E30: Recovery | F30: 5 | G30: 心拍 ≤140 | H30: 恢復跑 4〜5 km（與肌力同日，兩者都輕） | I30: 肌力日：Hyrox 或 15 分鐘核心＋臀腿 擇一，難度 6〜7，不要跑到心拍 160+
A31: 5 | B31: 46332 | C31: 五 | D31: 第二階段｜馬拉松訓練 | E31: Easy | F31: 6 | G31: 7:15〜7:45 / 心拍 140〜150 | H31: 輕鬆跑 6 km
A32: 5 | B32: 46333 | C32: 六 | D32: 第二階段｜馬拉松訓練 | E32: 休息 | F32: 0 | H32: 休息
A33: 5 | B33: 46334 | C33: 日 | D33: 第二階段｜馬拉松訓練 | E33: Long | F33: 22 | G33: 7:10〜7:40 / 心拍 ≤155 | H33: 長跑 22 km，最後 5 km @ 6:45 ★關卡1：最後5km穩6:45且心拍<168才繼續下面的MP段 | I33: 補給照 11/1，加鹽錠或電解質
A34: 6 | B34: 46335 | C34: 一 | D34: 第二階段｜馬拉松訓練 | E34: 休息 | F34: 0 | H34: 休息
A35: 6 | B35: 46336 | C35: 二 | D35: 第二階段｜馬拉松訓練 | E35: Recovery | F35: 6 | G35: 7:45+ / 心拍 ≤140 | H35: 恢復跑 6 km 非常慢
A36: 6 | B36: 46337 | C36: 三 | D36: 第二階段｜馬拉松訓練 | E36: MP | F36: 10 | G36: MP 段 6:40〜6:50 | H36: 2 km Easy + 7 km @ 6:40 + 1 km Easy | I36: 第一次連續 6 km MP，看心拍能否守在 165 以下
A37: 6 | B37: 46338 | C37: 四 | D37: 第二階段｜馬拉松訓練 | E37: Recovery | F37: 5 | G37: 心拍 ≤140 | H37: 恢復跑 4〜5 km（與肌力同日，兩者都輕） | I37: 肌力日：Hyrox 或 15 分鐘核心＋臀腿 擇一，難度 6〜7，不要跑到心拍 160+
A38: 6 | B38: 46339 | C38: 五 | D38: 第二階段｜馬拉松訓練 | E38: Easy | F38: 6 | G38: 7:15〜7:45 / 心拍 140〜150 | H38: 輕鬆跑 6 km
A39: 6 | B39: 46340 | C39: 六 | D39: 第二階段｜馬拉松訓練 | E39: 休息 | F39: 0 | H39: 休息
A40: 6 | B40: 46341 | C40: 日 | D40: 第二階段｜馬拉松訓練 | E40: Long | F40: 26 | G40: 7:10〜7:40 / 心拍 ≤155 | H40: 長跑 26 km，最後 6 km @ 6:45 | I40: 超過 2.5 小時就停，不硬撐距離
...

Sheet 週總覽
A1: 週 | B1: 起 | C1: 迄 | D1: 階段 | E1: 計畫總 km | F1: 長跑 km | G1: 實際總 km | H1: 達成率 | I1: 重點
A2: 1 | B2: 46303 | C2: 46306 | D2: 第一階段｜重建跑量 | E2: =SUM(課表!F2:F5) | F2: =MAX(課表!F2:F5) | G2: =SUM(課表!J2:J5) | H2: =IF(E2=0,"",G2/E2) | I2: 開始建立習慣
A3: 2 | B3: 46307 | C3: 46313 | D3: 第一階段｜重建跑量 | E3: =SUM(課表!F6:F12) | F3: =MAX(課表!F6:F12) | G3: =SUM(課表!J6:J12) | H3: =IF(E3=0,"",G3/E3) | I3: 長跑 14
A4: 3 | B4: 46314 | C4: 46320 | D4: 第一階段｜重建跑量 | E4: =SUM(課表!F13:F19) | F4: =MAX(課表!F13:F19) | G4: =SUM(課表!J13:J19) | H4: =IF(E4=0,"",G4/E4) | I4: 長跑 16，第一次坡跑
A5: 4 | B5: 46321 | C5: 46327 | D5: 第二階段｜馬拉松訓練 | E5: =SUM(課表!F20:F26) | F5: =MAX(課表!F20:F26) | G5: =SUM(課表!J20:J26) | H5: =IF(E5=0,"",G5/E5) | I5: 長跑 18，開始練補給
A6: 5 | B6: 46328 | C6: 46334 | D6: 第二階段｜馬拉松訓練 | E6: =SUM(課表!F27:F33) | F6: =MAX(課表!F27:F33) | G6: =SUM(課表!J27:J33) | H6: =IF(E6=0,"",G6/E6) | I6: 長跑 22
A7: 6 | B7: 46335 | C7: 46341 | D7: 第二階段｜馬拉松訓練 | E7: =SUM(課表!F34:F40) | F7: =MAX(課表!F34:F40) | G7: =SUM(課表!J34:J40) | H7: =IF(E7=0,"",G7/E7) | I7: 長跑 26（長跑最大週前的鋪墊）
A8: 7 | B8: 46342 | C8: 46348 | D8: 第三階段｜Peak | E8: =SUM(課表!F41:F47) | F8: =MAX(課表!F41:F47) | G8: =SUM(課表!J41:J47) | H8: =IF(E8=0,"",G8/E8) | I8: ★ 峰值 30 km 比賽預演
A9: 8 | B9: 46349 | C9: 46355 | D9: 第三階段｜Peak | E9: =SUM(課表!F48:F54) | F9: =MAX(課表!F48:F54) | G9: =SUM(課表!J48:J54) | H9: =IF(E9=0,"",G9/E9) | I9: 減量週，20 km 收尾 MP
A10: 9 | B10: 46356 | C10: 46362 | D10: 第四階段｜Taper | E10: =SUM(課表!F55:F61) | F10: =MAX(課表!F55:F61) | G10: =SUM(課表!J55:J61) | H10: =IF(E10=0,"",G10/E10) | I10: Taper 1
A11: 10 | B11: 46363 | C11: 46369 | D11: 第四階段｜Taper | E11: =SUM(課表!F62:F68) | F11: =MAX(課表!F62:F68) | G11: =SUM(課表!J62:J68) | H11: =IF(E11=0,"",G11/E11) | I11: Taper 2
A12: 11 | B12: 46370 | C12: 46370 | D12: 比賽日 | E12: =SUM(課表!F69:F69) | F12: =MAX(課表!F69:F69) | G12: =SUM(課表!J69:J69) | H12: =IF(E12=0,"",G12/E12) | I12: 🏁 12/14 比賽
D14: 合計 | E14: =SUM(E2:E12) | G14: =SUM(G2:G12)
